[{"name": "test.test_positive_list.PositiveList.test_calls", "status": "failed", "message": "Expected 'filter' to have been called.", "passed": false, "points": ["p01-17.1"], "backtrace": ["  File \"/usr/lib/python3.12/unittest/case.py\", line 58, in testPartExecutor\n    yield\n", "  File \"/usr/lib/python3.12/unittest/case.py\", line 634, in run\n    self._callTestMethod(testMethod)\n", "  File \"/usr/lib/python3.12/unittest/case.py\", line 589, in _callTestMethod\n    if method() is not None:\n       ^^^^^^^^\n", "  File \"/home/marco/python-data-analysis-helsinki/01-python/mooc-data-analysis-with-python-2024-2025/part01-e17_positive_list/test/test_positive_list.py\", line 35, in test_calls\n    f.assert_called()\n", "  File \"/usr/lib/python3.12/unittest/mock.py\", line 913, in assert_called\n    raise AssertionError(msg)\n"]}, {"name": "test.test_positive_list.PositiveList.test_first", "status": "failed", "message": "Lists differ: [] != [2, 1]\n\nSecond list contains 2 additional elements.\nFirst extra element 0:\n2\n\n- []\n+ [2, 1] : Wrong result for list [2, -2, 0, 1, -7]!", "passed": false, "points": ["p01-17.1"], "backtrace": ["  File \"/usr/lib/python3.12/unittest/case.py\", line 58, in testPartExecutor\n    yield\n", "  File \"/usr/lib/python3.12/unittest/case.py\", line 634, in run\n    self._callTestMethod(testMethod)\n", "  File \"/usr/lib/python3.12/unittest/case.py\", line 589, in _callTestMethod\n    if method() is not None:\n       ^^^^^^^^\n", "  File \"/home/marco/python-data-analysis-helsinki/01-python/mooc-data-analysis-with-python-2024-2025/part01-e17_positive_list/test/test_positive_list.py\", line 22, in test_first\n    self.assertEqual(result, [2,1], msg=\"Wrong result for list %s!\" % L)\n"]}, {"name": "test.test_positive_list.PositiveList.test_random", "status": "failed", "message": "Lists differ: [] != [90, 84, 72, 15, 72, 3, 79, 58, 49, 5, 54,[55 chars], 35]\n\nSecond list contains 26 additional elements.\nFirst extra element 0:\n90\n\n- []\n+ [90,\n+  84,\n+  72,\n+  15,\n+  72,\n+  3,\n+  79,\n+  58,\n+  49,\n+  5,\n+  54,\n+  18,\n+  54,\n+  94,\n+  65,\n+  16,\n+  30,\n+  56,\n+  32,\n+  19,\n+  33,\n+  14,\n+  71,\n+  78,\n+  51,\n+  35] : Wrong result for list [-33 -46 -16  90 -96 -24 -15 -71 -59  84  72 -20 -98  15  72 -90 -42 -31\n   3  79 -64  58 -77  49   5 -29 -91  54  -7  18  54 -76  94  65  16 -38\n  30 -32  56 -46  32 -10  19 -60  33  14  71  78  51  35]!", "passed": false, "points": ["p01-17.1"], "backtrace": ["  File \"/usr/lib/python3.12/unittest/case.py\", line 58, in testPartExecutor\n    yield\n", "  File \"/usr/lib/python3.12/unittest/case.py\", line 634, in run\n    self._callTestMethod(testMethod)\n", "  File \"/usr/lib/python3.12/unittest/case.py\", line 589, in _callTestMethod\n    if method() is not None:\n       ^^^^^^^^\n", "  File \"/home/marco/python-data-analysis-helsinki/01-python/mooc-data-analysis-with-python-2024-2025/part01-e17_positive_list/test/test_positive_list.py\", line 30, in test_random\n    self.assertEqual(result, correct, msg=\"Wrong result for list %s!\" % L)\n"]}]