[{"name": "unittest.loader._FailedTest.test.test_usemodule", "status": "errored", "message": "Failed to import test module: test.test_usemodule\nTraceback (most recent call last):\n  File \"/usr/lib/python3.12/unittest/loader.py\", line 394, in _find_test_path\n    module = self._get_module_from_name(name)\n             ^^^^^^^^^^^^^^^^^^^^^^^^^^^^^^^^\n  File \"/usr/lib/python3.12/unittest/loader.py\", line 337, in _get_module_from_name\n    __import__(name)\n  File \"/home/marco/python-data-analysis-helsinki/01-python/mooc-data-analysis-with-python-2024-2025/part01-e20_usemodule/test/test_usemodule.py\", line 13, in <module>\n    from src import usemodule\n  File \"/home/marco/python-data-analysis-helsinki/01-python/mooc-data-analysis-with-python-2024-2025/part01-e20_usemodule/src/usemodule.py\", line 12\n    if __name__ == \"__main__\":\n    ^^\nIndentationError: expected an indented block after function definition on line 9\n", "passed": false, "points": [], "backtrace": ["  File \"/usr/lib/python3.12/unittest/case.py\", line 58, in testPartExecutor\n    yield\n", "  File \"/usr/lib/python3.12/unittest/case.py\", line 634, in run\n    self._callTestMethod(testMethod)\n", "  File \"/usr/lib/python3.12/unittest/case.py\", line 589, in _callTestMethod\n    if method() is not None:\n       ^^^^^^^^\n", "  File \"/usr/lib/python3.12/unittest/loader.py\", line 33, in testFailure\n    raise self._exception\n"]}]